Workbook
Name TicketData: DataSheet!$I$30:$K$33
Name SinnerIDList: 'ID Level'!$I$2:$I$999
Name SinnerEGOData: 'EGO Tier'!$J$2:$K$999
Name SinnerEGOList: 'EGO Tier'!$J$2:$J$999
Name EGOShardNeeded: 'EGO Tier'!$N$2:$N$999
Name TicketList: DataSheet!$I$30:$I$33
Name IDExtractionList: 'ID Level'!$N$2:$N$999
Name EGOExtractionList: 'EGO Tier'!$M$2:$M$999
Name SinnerIDData: 'ID Level'!$I$2:$M$999
Name IDShardNeeded: 'ID Level'!$O$2:$O$999
Name FingerList: 'IF SS7 Sheet'!$F$15:$F$19
Name ShardNumber: DataSheet!$L$1:$N$12
Name SinnerList: DataSheet!$I$1:$I$12
Name SinnerAcronym: DataSheet!$H$1:$H$12
Name FingerList: 'IF SS8 Sheet'!$F$15:$F$19
Name LevelRange: DataSheet!$A$2:$A$101
Name ManagerXPData: DataSheet!$D$2:$G$201
Name SinnerShard: DataSheet!$I$1:$J$12
Name IDLevelRange: DataSheet!$A$2:$C$101
Name ShardUsage: DataSheet!$L$1:$L$12

Sheet Lunacy
A1: Lunacy Total | B1: Paid Lunacy | C1: Free Lunacy | D1: Extraction Ticket | E1: Decaextraction Ticket | F1: Total Rolls | G1: 46198.182 | H1: =Inventory!K14 -> Tue
A2: 38996 | B2: 2841 | C2: =A2-B2 -> 36155 | D2: 23 | E2: 0 | F2: =SUM(F3:F4) -> 301
B3: 10 Rolls | C3: =(C2-MOD(C2,1300))/130 -> 270 | D3: =(D2-MOD(D2,10)) -> 20 | E3: =E2*10 -> 0 | F3: =SUM(C3:E3) -> 290
B4: 1 Roll After | C4: =ROUNDDOWN((MOD(C2,1300))/130,0) -> 8 | D4: =D2-(D2-MOD(D2,10)) -> 3 | E4: 0 | F4: =SUM(C4:E4) -> 11
B5: Leftover Lunacy | C5: =C2-C3*130 -> 1055
A6: Next Week Projection | G6: Next Week Projection | M6: Next Week Projection
A7: MD Lunacy | B7: =C2+750 -> 36905 | C7: =G1+7 -> 46205.182 | G7: MD Lunacy | H7: =B80+750 -> 44289 | I7: =C79+7 -> 46296.182 | M7: MD Lunacy | N7: =H80+750 -> 51673 | O7: =I79+7 -> 46387.182
A8: - 7 Daily Convert | B8: =B7-(7*26) -> 36723 | C8: =$D$2 -> 23 | D8: =$E$2 -> 0 | E8: =E9+E10 -> 305 | G8: - 7 Daily Convert | H8: =H7-(7*26) -> 44107 | I8: =$D$2 -> 23 | J8: =$E$2 -> 0 | K8: =K9+K10 -> 362 | M8: - 7 Daily Convert | N8: =N7-(7*26) -> 51491 | O8: =$D$2 -> 23 | P8: =$E$2 -> 0 | Q8: =Q9+Q10 -> 419
A9: 10 Rolls | B9: =(B8-MOD(B8,1300))/130 -> 280 | C9: =(C8-MOD(C8,10)) -> 20 | D9: =D8*10 -> 0 | E9: =B9+C9+D9 -> 300 | G9: 10 Rolls | H9: =(H8-MOD(H8,1300))/130 -> 330 | I9: =(I8-MOD(I8,10)) -> 20 | J9: =J8*10 -> 0 | K9: =H9+I9+J9 -> 350 | M9: 10 Rolls | N9: =(N8-MOD(N8,1300))/130 -> 390 | O9: =(O8-MOD(O8,10)) -> 20 | P9: =P8*10 -> 0 | Q9: =N9+O9+P9 -> 410
A10: 1 Roll After | B10: =ROUNDDOWN((MOD(B8,1300))/130,0) -> 2 | C10: =C8-(C8-MOD(C8,10)) -> 3 | D10: 0 | E10: =B10+C10+D10 -> 5 | G10: 1 Roll After | H10: =ROUNDDOWN((MOD(H8,1300))/130,0) -> 9 | I10: =I8-(I8-MOD(I8,10)) -> 3 | J10: 0 | K10: =H10+I10+J10 -> 12 | M10: 1 Roll After | N10: =ROUNDDOWN((MOD(N8,1300))/130,0) -> 6 | O10: =O8-(O8-MOD(O8,10)) -> 3 | P10: 0 | Q10: =N10+O10+P10 -> 9
A12: Next Week Projection | G12: Next Week Projection | M12: Next Week Projection
A13: MD Lunacy | B13: =B8+750 -> 37473 | C13: =C7+7 -> 46212.182 | G13: MD Lunacy | H13: =H8+750 -> 44857 | I13: =I7+7 -> 46303.182 | M13: MD Lunacy | N13: =N8+750 -> 52241 | O13: =O7+7 -> 46394.182
A14: - 7 Daily Convert | B14: =B13-(7*26) -> 37291 | C14: =$D$2 -> 23 | D14: =$E$2 -> 0 | E14: =E15+E16 -> 309 | G14: - 7 Daily Convert | H14: =H13-(7*26) -> 44675 | I14: =$D$2 -> 23 | J14: =$E$2 -> 0 | K14: =K15+K16 -> 366 | M14: - 7 Daily Convert | N14: =N13-(7*26) -> 52059 | O14: =$D$2 -> 23 | P14: =$E$2 -> 0 | Q14: =Q15+Q16 -> 423
A15: 10 Rolls | B15: =(B14-MOD(B14,1300))/130 -> 280 | C15: =(C14-MOD(C14,10)) -> 20 | D15: =D14*10 -> 0 | E15: =B15+C15+D15 -> 300 | G15: 10 Rolls | H15: =(H14-MOD(H14,1300))/130 -> 340 | I15: =(I14-MOD(I14,10)) -> 20 | J15: =J14*10 -> 0 | K15: =H15+I15+J15 -> 360 | M15: 10 Rolls | N15: =(N14-MOD(N14,1300))/130 -> 400 | O15: =(O14-MOD(O14,10)) -> 20 | P15: =P14*10 -> 0 | Q15: =N15+O15+P15 -> 420
A16: 1 Roll After | B16: =ROUNDDOWN((MOD(B14,1300))/130,0) -> 6 | C16: =C14-(C14-MOD(C14,10)) -> 3 | D16: 0 | E16: =B16+C16+D16 -> 9 | G16: 1 Roll After | H16: =ROUNDDOWN((MOD(H14,1300))/130,0) -> 3 | I16: =I14-(I14-MOD(I14,10)) -> 3 | J16: 0 | K16: =H16+I16+J16 -> 6 | M16: 1 Roll After | N16: =ROUNDDOWN((MOD(N14,1300))/130,0) -> 0 | O16: =O14-(O14-MOD(O14,10)) -> 3 | P16: 0 | Q16: =N16+O16+P16 -> 3
A18: Next Week Projection | G18: Next Week Projection | M18: Next Week Projection
A19: MD Lunacy | B19: =B14+750 -> 38041 | C19: =C13+7 -> 46219.182 | G19: MD Lunacy | H19: =H14+750 -> 45425 | I19: =I13+7 -> 46310.182 | M19: MD Lunacy | N19: =N14+750 -> 52809 | O19: =O13+7 -> 46401.182
A20: - 7 Daily Convert | B20: =B19-(7*26) -> 37859 | C20: =$D$2 -> 23 | D20: =$E$2 -> 0 | E20: =E21+E22 -> 314 | G20: - 7 Daily Convert | H20: =H19-(7*26) -> 45243 | I20: =$D$2 -> 23 | J20: =$E$2 -> 0 | K20: =K21+K22 -> 371 | M20: - 7 Daily Convert | N20: =N19-(7*26) -> 52627 | O20: =$D$2 -> 23 | P20: =$E$2 -> 0 | Q20: =Q21+Q22 -> 427
A21: 10 Rolls | B21: =(B20-MOD(B20,1300))/130 -> 290 | C21: =(C20-MOD(C20,10)) -> 20 | D21: =D20*10 -> 0 | E21: =B21+C21+D21 -> 310 | G21: 10 Rolls | H21: =(H20-MOD(H20,1300))/130 -> 340 | I21: =(I20-MOD(I20,10)) -> 20 | J21: =J20*10 -> 0 | K21: =H21+I21+J21 -> 360 | M21: 10 Rolls | N21: =(N20-MOD(N20,1300))/130 -> 400 | O21: =(O20-MOD(O20,10)) -> 20 | P21: =P20*10 -> 0 | Q21: =N21+O21+P21 -> 420
A22: 1 Roll After | B22: =ROUNDDOWN((MOD(B20,1300))/130,0) -> 1 | C22: =C20-(C20-MOD(C20,10)) -> 3 | D22: 0 | E22: =B22+C22+D22 -> 4 | G22: 1 Roll After | H22: =ROUNDDOWN((MOD(H20,1300))/130,0) -> 8 | I22: =I20-(I20-MOD(I20,10)) -> 3 | J22: 0 | K22: =H22+I22+J22 -> 11 | M22: 1 Roll After | N22: =ROUNDDOWN((MOD(N20,1300))/130,0) -> 4 | O22: =O20-(O20-MOD(O20,10)) -> 3 | P22: 0 | Q22: =N22+O22+P22 -> 7
A24: Next Week Projection | G24: Next Week Projection | M24: Next Week Projection
A25: MD Lunacy | B25: =B20+750 -> 38609 | C25: =C19+7 -> 46226.182 | G25: MD Lunacy | H25: =H20+750 -> 45993 | I25: =I19+7 -> 46317.182 | M25: MD Lunacy | N25: =N20+750 -> 53377 | O25: =O19+7 -> 46408.182
A26: - 7 Daily Convert | B26: =B25-(7*26) -> 38427 | C26: =$D$2 -> 23 | D26: =$E$2 -> 0 | E26: =E27+E28 -> 318 | G26: - 7 Daily Convert | H26: =H25-(7*26) -> 45811 | I26: =$D$2 -> 23 | J26: =$E$2 -> 0 | K26: =K27+K28 -> 375 | M26: - 7 Daily Convert | N26: =N25-(7*26) -> 53195 | O26: =$D$2 -> 23 | P26: =$E$2 -> 0 | Q26: =Q27+Q28 -> 432
A27: 10 Rolls | B27: =(B26-MOD(B26,1300))/130 -> 290 | C27: =(C26-MOD(C26,10)) -> 20 | D27: =D26*10 -> 0 | E27: =B27+C27+D27 -> 310 | G27: 10 Rolls | H27: =(H26-MOD(H26,1300))/130 -> 350 | I27: =(I26-MOD(I26,10)) -> 20 | J27: =J26*10 -> 0 | K27: =H27+I27+J27 -> 370 | M27: 10 Rolls | N27: =(N26-MOD(N26,1300))/130 -> 400 | O27: =(O26-MOD(O26,10)) -> 20 | P27: =P26*10 -> 0 | Q27: =N27+O27+P27 -> 420
A28: 1 Roll After | B28: =ROUNDDOWN((MOD(B26,1300))/130,0) -> 5 | C28: =C26-(C26-MOD(C26,10)) -> 3 | D28: 0 | E28: =B28+C28+D28 -> 8 | G28: 1 Roll After | H28: =ROUNDDOWN((MOD(H26,1300))/130,0) -> 2 | I28: =I26-(I26-MOD(I26,10)) -> 3 | J28: 0 | K28: =H28+I28+J28 -> 5 | M28: 1 Roll After | N28: =ROUNDDOWN((MOD(N26,1300))/130,0) -> 9 | O28: =O26-(O26-MOD(O26,10)) -> 3 | P28: 0 | Q28: =N28+O28+P28 -> 12
A30: Next Week Projection | G30: Next Week Projection | M30: Next Week Projection
A31: MD Lunacy | B31: =B26+750 -> 39177 | C31: =C25+7 -> 46233.182 | G31: MD Lunacy | H31: =H26+750 -> 46561 | I31: =I25+7 -> 46324.182 | M31: MD Lunacy | N31: =N26+750 -> 53945 | O31: =O25+7 -> 46415.182
A32: - 7 Daily Convert | B32: =B31-(7*26) -> 38995 | C32: =$D$2 -> 23 | D32: =$E$2 -> 0 | E32: =E33+E34 -> 322 | G32: - 7 Daily Convert | H32: =H31-(7*26) -> 46379 | I32: =$D$2 -> 23 | J32: =$E$2 -> 0 | K32: =K33+K34 -> 379 | M32: - 7 Daily Convert | N32: =N31-(7*26) -> 53763 | O32: =$D$2 -> 23 | P32: =$E$2 -> 0 | Q32: =Q33+Q34 -> 436
A33: 10 Rolls | B33: =(B32-MOD(B32,1300))/130 -> 290 | C33: =(C32-MOD(C32,10)) -> 20 | D33: =D32*10 -> 0 | E33: =B33+C33+D33 -> 310 | G33: 10 Rolls | H33: =(H32-MOD(H32,1300))/130 -> 350 | I33: =(I32-MOD(I32,10)) -> 20 | J33: =J32*10 -> 0 | K33: =H33+I33+J33 -> 370 | M33: 10 Rolls | N33: =(N32-MOD(N32,1300))/130 -> 410 | O33: =(O32-MOD(O32,10)) -> 20 | P33: =P32*10 -> 0 | Q33: =N33+O33+P33 -> 430
A34: 1 Roll After | B34: =ROUNDDOWN((MOD(B32,1300))/130,0) -> 9 | C34: =C32-(C32-MOD(C32,10)) -> 3 | D34: 0 | E34: =B34+C34+D34 -> 12 | G34: 1 Roll After | H34: =ROUNDDOWN((MOD(H32,1300))/130,0) -> 6 | I34: =I32-(I32-MOD(I32,10)) -> 3 | J34: 0 | K34: =H34+I34+J34 -> 9 | M34: 1 Roll After | N34: =ROUNDDOWN((MOD(N32,1300))/130,0) -> 3 | O34: =O32-(O32-MOD(O32,10)) -> 3 | P34: 0 | Q34: =N34+O34+P34 -> 6
A36: Next Week Projection | G36: Next Week Projection | M36: Next Week Projection
A37: MD Lunacy | B37: =B32+750 -> 39745 | C37: =C31+7 -> 46240.182 | G37: MD Lunacy | H37: =H32+750 -> 47129 | I37: =I31+7 -> 46331.182 | M37: MD Lunacy | N37: =N32+750 -> 54513 | O37: =O31+7 -> 46422.182
A38: - 7 Daily Convert | B38: =B37-(7*26) -> 39563 | C38: =$D$2 -> 23 | D38: =$E$2 -> 0 | E38: =E39+E40 -> 327 | G38: - 7 Daily Convert | H38: =H37-(7*26) -> 46947 | I38: =$D$2 -> 23 | J38: =$E$2 -> 0 | K38: =K39+K40 -> 384 | M38: - 7 Daily Convert | N38: =N37-(7*26) -> 54331 | O38: =$D$2 -> 23 | P38: =$E$2 -> 0 | Q38: =Q39+Q40 -> 440
A39: 10 Rolls | B39: =(B38-MOD(B38,1300))/130 -> 300 | C39: =(C38-MOD(C38,10)) -> 20 | D39: =D38*10 -> 0 | E39: =B39+C39+D39 -> 320 | G39: 10 Rolls | H39: =(H38-MOD(H38,1300))/130 -> 360 | I39: =(I38-MOD(I38,10)) -> 20 | J39: =J38*10 -> 0 | K39: =H39+I39+J39 -> 380 | M39: 10 Rolls | N39: =(N38-MOD(N38,1300))/130 -> 410 | O39: =(O38-MOD(O38,10)) -> 20 | P39: =P38*10 -> 0 | Q39: =N39+O39+P39 -> 430
A40: 1 Roll After | B40: =ROUNDDOWN((MOD(B38,1300))/130,0) -> 4 | C40: =C38-(C38-MOD(C38,10)) -> 3 | D40: 0 | E40: =B40+C40+D40 -> 7 | G40: 1 Roll After | H40: =ROUNDDOWN((MOD(H38,1300))/130,0) -> 1 | I40: =I38-(I38-MOD(I38,10)) -> 3 | J40: 0 | K40: =H40+I40+J40 -> 4 | M40: 1 Roll After | N40: =ROUNDDOWN((MOD(N38,1300))/130,0) -> 7 | O40: =O38-(O38-MOD(O38,10)) -> 3 | P40: 0 | Q40: =N40+O40+P40 -> 10
A42: Next Week Projection | G42: Next Week Projection | M42: Next Week Projection
A43: MD Lunacy | B43: =B38+750 -> 40313 | C43: =C37+7 -> 46247.182 | G43: MD Lunacy | H43: =H38+750 -> 47697 | I43: =I37+7 -> 46338.182 | M43: MD Lunacy | N43: =N38+750 -> 55081 | O43: =O37+7 -> 46429.182
A44: - 7 Daily Convert | B44: =B43-(7*26) -> 40131 | C44: =$D$2 -> 23 | D44: =$E$2 -> 0 | E44: =E45+E46 -> 331 | G44: - 7 Daily Convert | H44: =H43-(7*26) -> 47515 | I44: =$D$2 -> 23 | J44: =$E$2 -> 0 | K44: =K45+K46 -> 388 | M44: - 7 Daily Convert | N44: =N43-(7*26) -> 54899 | O44: =$D$2 -> 23 | P44: =$E$2 -> 0 | Q44: =Q45+Q46 -> 445
A45: 10 Rolls | B45: =(B44-MOD(B44,1300))/130 -> 300 | C45: =(C44-MOD(C44,10)) -> 20 | D45: =D44*10 -> 0 | E45: =B45+C45+D45 -> 320 | G45: 10 Rolls | H45: =(H44-MOD(H44,1300))/130 -> 360 | I45: =(I44-MOD(I44,10)) -> 20 | J45: =J44*10 -> 0 | K45: =H45+I45+J45 -> 380 | M45: 10 Rolls | N45: =(N44-MOD(N44,1300))/130 -> 420 | O45: =(O44-MOD(O44,10)) -> 20 | P45: =P44*10 -> 0 | Q45: =N45+O45+P45 -> 440
A46: 1 Roll After | B46: =ROUNDDOWN((MOD(B44,1300))/130,0) -> 8 | C46: =C44-(C44-MOD(C44,10)) -> 3 | D46: 0 | E46: =B46+C46+D46 -> 11 | G46: 1 Roll After | H46: =ROUNDDOWN((MOD(H44,1300))/130,0) -> 5 | I46: =I44-(I44-MOD(I44,10)) -> 3 | J46: 0 | K46: =H46+I46+J46 -> 8 | M46: 1 Roll After | N46: =ROUNDDOWN((MOD(N44,1300))/130,0) -> 2 | O46: =O44-(O44-MOD(O44,10)) -> 3 | P46: 0 | Q46: =N46+O46+P46 -> 5
...

Sheet Inventory
A1: 15 | B1: 5 | C1: 5 | D1: 15 | E1: 10 | F1: 25 | G1: 20 | H1: Yi Sang | I1: EGO | J1: YS | L1: =I8+(DataSheet!J38*3)+DataSheet!J35 -> 4251 | M1: =VLOOKUP(M9, IDLevelRange, 3, FALSE) -> 251629
A2: 80 | B2: 20 | C2: 80 | D2: 10 | E2: 10 | F2: 6 | G2: 20 | H2: 1Star | I2: 1 | J2: Thumb | L2: =L1+(DataSheet!J38*3)+DataSheet!J35 -> 4491 | M2: =VLOOKUP(M10, IDLevelRange, 3, FALSE) -> 251629
A3: {=A2:G2-A9:G9} -> 0 | B3: 0 | C3: 0 | D3: 0 | E3: 0 | F3: 0 | G3: 0 | H3: 6 | I3: 2 | J3: Thurs | L3: =L2+(DataSheet!J38*3)+DataSheet!J35 -> 4731 | M3: =M2-M1-N9 -> 0
A4: =SWITCH(A15, "EGO", 1000, "000 ID", 1000, "00 ID", 500) -> 1000 | B4: 500 | C4: 250 | D4: 750 | E4: 200 | F4: 600 | H4: Sinner Full Name Conditional Formatting | I4: Sharding Type Conditional Formatting | J4: Sinner Acronym Conditional Formatting | L4: =L3+(DataSheet!J38*3)+DataSheet!J35 -> 4971 | M4: =MOD(M3, N4) -> 0 | N4: {=VLOOKUP(L11:L14, TicketData, 3, FALSE)} -> 3000
A5: {=SEQUENCE(1, 6, 1, 0)} -> 1 | B5: 1 | C5: 1 | D5: 1 | E5: 1 | F5: 1 | H5: Sharding Type Conditional Formatting | I5: Sinner Canto Level Conditional Formatting | J5: Finger IDs Conditional Formatting | L5: =L4+(DataSheet!J38*3)+DataSheet!J35 -> 5211 | M5: =MOD(M4, N5) -> 0 | N5: 1000
A6: {=A5:F5-A11:F11} -> 0 | B6: 0 | C6: 1 | D6: 0 | E6: 0 | F6: 1 | H6: Day (Num) of week Conditional Formatting | I6: Weekly Pass Conditional Formatting | J6: Day of week Conditional Formatting | L6: =L5+(DataSheet!J38*3)+DataSheet!J35 -> 5451 | M6: =MOD(M5, N6) -> 0 | N6: 200
L7: =L6+(DataSheet!J38*3)+DataSheet!J35 -> 5691 | M7: =MOD(M6, N7) -> 0 | N7: 50
A8: IV Ticket | B8: III Ticket | C8: Threads | D8: Crates | E8: Random Crates | F8: Enkephalin Box | G8: Extraction Ticket | H8: Current XP | I8: 4011 | J8: Manager Level | K8: Next Level Enkephalin | L8: ID to Level Up | M8: [Blade Lineage Mentor] Meursault
A9: 80 | B9: 20 | C9: 80 | D9: 10 | E9: 10 | F9: 6 | G9: 20 | H9: Next Level XP | I9: =VLOOKUP(J9, ManagerXPData, 2) -> 4316 | J9: 83 | K9: =IF(VLOOKUP(J9+1, ManagerXPData, 4) = 0, "0", "+1") -> 0 | L9: ID Experience | M9: =VLOOKUP(M8, SinnerIDData, 2, false) -> 60 | N9: =VLOOKUP(M8, SinnerIDData, 3, false) -> 0 | P9: Next Nominable | Q9: Event Unit | R9: Extractible Unit
A10: ID/EGO Reward | B10: Announcer | C10: Banner | D10: Banner Effect | E10: Ticket | F10: Ticket Effect | H10: {=MAP(SEQUENCE(7,1), LAMBDA(x, "After " & x & " Daily"))} -> After 1 Daily | I10: {=L1:L7} -> 4251 | J10: {=MAP(I10:I16, LAMBDA(val, "After 1 MD: " & (val + 100)))} -> After 1 MD: 4351 | L10: ID Level Target | M10: 60 | N10: Ticket Left After | P10: S1 | R10: N Corp MS
A11: TRUE | B11: TRUE | C11: FALSE | D11: TRUE | E11: TRUE | F11: FALSE | H11: After 2 Daily | I11: 4491 | J11: After 1 MD: 4591 | L11: Ticket IV | M11: {=(M3:M6-M4:M7)/VLOOKUP(L11:L14, TicketData, 3, FALSE)} -> 0 | N11: {=VLOOKUP(L11:L14, TicketData, 2, FALSE)-M11:M14} -> 287 | O11: 56 | P11: S2 | Q11: Molar OT | R11: Spicebush YS | S11: Sunshower HC | T11: RSP RD
A12: Event Currency Required | B12: {=SUM(MAP(A1:G1, A3:G3, LAMBDA(x, y, x*y)), MAP(A4:F4, A6:F6, LAMBDA(a, b, a*b)))} -> 850 | C12: Event Currency Needed | D12: =B12-(C6*C4)-(E6*E4) -> 600 | E12: Current Currency | F12: 192 | H12: After 3 Daily | I12: 4731 | J12: After 1 MD: 4831 | L12: Ticket III | M12: 0 | N12: 298 | O12: 67 | P12: S3 | R12: Pequod IS | S12: Pequod HC | T12: Pirate GG
B13: =B12-F12 -> 658 | D13: =D12-F12 -> 408 | E13: Extractible EGO | H13: After 4 Daily | I13: 4971 | J13: After 1 MD: 5071 | L13: Ticket II | M13: 0 | N13: 286 | O13: 55 | P13: S4 | Q13: MC FT | R13: WH GG | S13: WH RS
A14: Reward Type | E14: Extractible ID | H14: After 5 Daily | I14: 5211 | J14: After 1 MD: 5311 | K14: Tue | L14: Ticket I | M14: 0 | N14: 52 | O14: 10 | P14: S5 | Q14: KK IS | R14: Mancha GG | S14: Firefist GG | T14: Mancha OT
A15: 000 ID | E15: Need-to-Shard EGO | H15: After 6 Daily | I15: 5451 | J15: After 1 MD: 5551 | K15: Gacha Pull Result | M15: Mirror Dungeon Schedules | Q15: KK HC
E16: Need-to-Shard ID | H16: After 7 Daily | I16: 5691 | J16: After 1 MD: 5791 | K16: Yi Sang | L16: 1Star | M16: Rental | N16: TRUE | P16: SF | Q16: Liu YS | R16: Cinq DQ | S16: Zwei IS | T16: R MS
A17: Sinner: | B17: Yi Sang | C17: This Week Projection | D17: =LET(formula, (F19+H18+(0.4*I18)+(H20*7.5)+(I20*8)+(J20*9.5)+(SUMPRODUCT(H22:J22)*3)), D19 + (formula-ROUNDDOWN(F19,0))*3) -> 2496 | H17: Daily left | I17: Weekly left | J17: Normal left total | K17: Week til Season end | L17: Uptying Sinner | M17: Poise Rupture | N17: FALSE | Q17: R HC | R17: R IS | S17: W OT | T17: W RS
A18: Shard Type | B18: EGO/3 Star | C18: Crate Required | D18: =SUM(B29:M29) -> 1811.5 | E18: Pass Level Requirement | F18: =ROUNDUP(D20/3,0) -> 0 | H18: 1 | I18: 0 | J18: 20 | K18: 7 | L18: Ishmael | M18: Tremor | N18: FALSE | P18: Walp | Q18: FS HC | R18: MB OT | S18: RE&P RS | T18: Regret FT
A19: Shard Needed | B19: =VLOOKUP(B18, ShardNumber, 2, FALSE) -> 400 | C19: Crate Posessed | D19: =DataSheet!J13 -> 2493 | E19: Current Pass Level | F19: =DataSheet!J14 -> 1201 | H19: {=SEQUENCE(1, 3) & " Hard Left"} -> 1 Hard Left | I19: 2 Hard Left | J19: 3 Hard Left | K19: =(K18*3)+ROUNDDOWN(K18/2,0) -> 24 | L19: =J18-K19 -> -4 | M19: Sinking | N19: FALSE
A20: Shard Possesed | B20: =VLOOKUP(B17, SinnerShard, 2, FALSE) -> 5 | C20: Crate to Grind | D20: =MAX(0, D18-D19) -> 0 | E20: Pass Level goal | F20: =F19+F18 -> 1201 | H20: FALSE | I20: FALSE | J20: FALSE | K20: FALSE | M20: Burn | N20: FALSE
A21: Crate to Open | B21: =B22/2 -> 197.5 | C21: Crate final Projection | D21: =ROUNDDOWN(F22-F19,0)*3+D19 -> 3390 | E21: Pass level will gain | F21: =(34*K18)+(H18)+(0.4*I18)+((H20*7.5)+(I20*8)+(J20*9.5))+(J18*3) -> 299 | H21: Poise Rupture | I21: Sinking | J21: Bleed | K21: Rental | M21: Bleed | N21: FALSE
A22: Shard Required | B22: =B19-B20 -> 395 | C22: 000 Current Capable | D22: =ROUNDDOWN(D19*2/400,0) -> 12 | E22: Pass level final | F22: =F19+F21 -> 1500 | H22: FALSE | I22: FALSE | J22: FALSE | K22: 1 | M22: Charge | N22: FALSE
C23: 000 SS End Capable | D23: =ROUNDDOWN(D21*2/400,0) -> 16 | E23: This Week Projection | F23: {=LET(formula, (F19+H18+(0.4*I18)+(H20*7.5)+(I20*8)+(J20*9.5)+(SUMPRODUCT(H22:J22)*3)), TEXT(formula, "0") & " / " & TEXT(formula + K20*3, "0"))} -> 1202 / 1202 | H23: Tremor | I23: Burn | J23: Charge | M23: Hard | N23: Normal
B24: FALSE | C24: TRUE | D24: FALSE | E24: TRUE | F24: TRUE | G24: TRUE | H24: TRUE | I24: TRUE | J24: TRUE | K24: TRUE | L24: TRUE | M24: TRUE
A25: Sinner | B25: Yi Sang | C25: Faust | D25: Don Quixote | E25: Ryoshu | F25: Meursault | G25: Hong Lu | H25: Heathcliff | I25: Ishmael | J25: Rodion | K25: Sinclair | L25: Outis | M25: Gregor
A26: Shard Type | B26: EGO/3 Star | C26: 2 3 Star + UT4 | D26: EGO/3 Star | E26: 3 Star UT | F26: EGO/3 Star | G26: EGO/3 Star | H26: 3 Star UT | I26: EGO/3 Star | J26: 2 3 Star | K26: 3 Star UT | L26: 3 Star UT | M26: EGO/3 Star
A27: {={"Shard Needed", MAP(B26:M26, LAMBDA(x, VLOOKUP(x, ShardNumber, 2, FALSE)))}} -> Shard Needed | B27: 400 | C27: 900 | D27: 400 | E27: 450 | F27: 400 | G27: 400 | H27: 450 | I27: 400 | J27: 800 | K27: 450 | L27: 450 | M27: 400 | N27: =IFERROR(__xludf.DUMMYFUNCTION("BYROW(B27:M27, LAMBDA(row, SPARKLINE(row, {""charttype"", ""column""})))"),"")
A28: {={"Shard Posessed", MAP(B25:M25, LAMBDA(x, VLOOKUP(x, SinnerShard, 2, FALSE)))}} -> Shard Posessed | B28: 5 | C28: 68 | D28: 20 | E28: 113 | F28: 16 | G28: 215 | H28: 57 | I28: 299 | J28: 416 | K28: 61 | L28: 135 | M28: 97 | N28: =IFERROR(__xludf.DUMMYFUNCTION("BYROW(B28:M28, LAMBDA(row, SPARKLINE(row, {""charttype"", ""column""})))"),"")
A29: {={"Crate Needed", LET(formula, (((B27:M27-B28:M28)/2)*B24:M24), IF(formula < 0, 0, formula))}} -> Crate Needed | B29: 0 | C29: 416 | D29: 0 | E29: 168.5 | F29: 192 | G29: 92.5 | H29: 196.5 | I29: 50.5 | J29: 192 | K29: 194.5 | L29: 157.5 | M29: 151.5 | N29: =IFERROR(__xludf.DUMMYFUNCTION("BYROW(B29:M29, LAMBDA(row, SPARKLINE(row, {""charttype"", ""column""})))"),"")
A30: ID/EGO to Shard | B30: Walp SS7 | C30: Index Proselyte+UT | D30: Walp SS7 | E30: Araya+UT | F30: Shadow-Vested | G30: Dim Shred | H30: Thumb Apprentice+UT | I30: Kurokumo | J30: Into the Sunset | K30: Pinky App+UT | L30: Middle Father+UT | M30: Firefist?
C31: Ring Apprentice+UT | J31: Thumb Mother | M31: Priest | N31: UT/TS Threads
A32: {={"Thread Needed", MAP(B26:M26, LAMBDA(x, VLOOKUP(x, ShardNumber, 3, FALSE)))}} -> Thread Needed | B32: 0 | C32: 500 | D32: 0 | E32: 250 | F32: 0 | G32: 0 | H32: 250 | I32: 0 | J32: 0 | K32: 250 | L32: 250 | M32: 0 | N32: =SUM(B32:M32) -> 1500
A33: Confirmed | B33: Index Father P Bu S | C33: Index Proselyte P S | D33: Index Proxy P S | E33: FA&S S T | F33: Hornet Bu Bl | G33: Ring Father C Bl | H33: Middle-Ricardo Bu Bl T | I33: Middle App Bu Bl | J33: Ring Docent Bl S | K33: Pinky App P Bl | L33: LCA Udjat S T | M33: Hoen Lamp Bu S | N33: Days Needed
A34: Assumed | C34: Ring App C Bl | E34: Araya Bu P Bl | F34: Ring Student Bl S | G34: S Corp P Bl | H34: Thumb App Bu T | I34: LCD Osir P Bl | J34: Thumb Mother P Bu T | K34: Wayfarer? C T | L34: Middle Father Bu Bl | M34: Hoen AEDD C R | N34: =MAX(0, ROUNDUP((N32-DataSheet!J15)/DataSheet!J28,0)) -> 0
A35: Guessed? | C35: Ardor-Blossom EGO Bu | F35: Shadow-Vested EGO P Bl | J35: Into the Sunset EGO Bu Bl | K35: Harmony EGO Bu Bl | N35: {="Burn: " & COUNTIF(B33:M35, "* Bu*")} -> Burn: 12 | O35: This Season (Assumed)
B36: 1Star | C36: 1Star | D36: 1Star | E36: 1Star | F36: 1Star | G36: 1Star | H36: 1Star | I36: 1Star | J36: 1Star | K36: 1Star | L36: 2Star | M36: 1Star | N36: {="Bleed: " & COUNTIF(B33:M35, "* Bl*")} -> Bleed: 15
N37: {="Tremor: " & COUNTIF(B33:M35, "* T*")} -> Tremor: 7
N38: {="Rupture: " & COUNTIF(B33:M35, "* R*")} -> Rupture: 1
N39: {="Sinking: " & COUNTIF(B33:M35, "* S*")} -> Sinking: 9
A40: Backlog Shard | B40: Fell-Bullet EGO P Bl | F40: Capote Bu T | H40: Kurokumo Bl | I40: Kurokumo Bl | K40: Hex Nail? Bl | L40: Barber Bl R | M40: Firefist Bu | N40: {="Poise: " & COUNTIF(B33:M35, "* P*")} -> Poise: 9
...

Sheet DataSheet
A1: =IFERROR(__xludf.DUMMYFUNCTION("IMPORTRANGE(""https://docs.google.com/spreadsheets/d/1dd1acJ31L_d8P07yRYqTDtptU4oCbycYLGhD8VBmbrI/edit?pli=1&gid=1870766492#gid=1870766492"", ""Sheet1!A1:B61"")"),"Level") -> Level | B1: =IFERROR(__xludf.DUMMYFUNCTION("""COMPUTED_VALUE"""),"Exp") -> Exp | C1: Total XP | D1: Manager Level | E1: Manager Level XP | F1: Max Enkephalin | G1: Max Increase | H1: YS | I1: Yi Sang | J1: 5 | K1: 00 SUM | L1: EGO/3 Star | M1: 400 | N1: 0 | O1: {={TOROW(MAKEARRAY(3, 5, LAMBDA(r, c, INDEX({"00"; "000"; "EGO"}, r) & " T" & (c - 1))), 0, FALSE), "EGO T5" ; BYCOL(O3:AD1000, LAMBDA(col, IF(COUNTA(col)=0, 0, COUNTA(col) - COUNTIF(col, " ??"))))}} -> 00 T0 | P1: 00 T1 | Q1: 00 T2 | R1: 00 T3 | S1: 00 T4 | T1: 000 T0 | U1: 000 T1 | V1: 000 T2 | W1: 000 T3 | X1: 000 T4 | Y1: EGO T0 | Z1: EGO T1 | AA1: EGO T2 | AB1: EGO T3 | AC1: EGO T4 | AD1: EGO T5 | AE1: Difference Between Manager Level
A2: =IFERROR(__xludf.DUMMYFUNCTION("""COMPUTED_VALUE"""),1.0) -> 1 | B2: =IFERROR(__xludf.DUMMYFUNCTION("""COMPUTED_VALUE"""),0.0) -> 0 | C2: =B2 -> 0 | D2: {=SEQUENCE(400,1)} -> 1 | E2: 15 | F2: 60 | G2: 0 | H2: FT | I2: Faust | J2: 68 | K2: =SUM(O2:S2) -> 51 | L2: 2 3 Star + UT4 | M2: 900 | N2: =N10*2 -> 500 | O2: 4 | P2: 8 | Q2: 1 | R2: 36 | S2: 2 | T2: 49 | U2: 2 | V2: 0 | W2: 19 | X2: 48 | Y2: 55 | Z2: 0 | AA2: 0 | AB2: 46 | AC2: 8 | AD2: 0
A3: =IFERROR(__xludf.DUMMYFUNCTION("""COMPUTED_VALUE"""),2.0) -> 2 | B3: =IFERROR(__xludf.DUMMYFUNCTION("""COMPUTED_VALUE"""),10.0) -> 10 | C3: =B3+C2 -> 10 | D3: 2 | E3: 30 | F3: =F2+G3 -> 63 | G3: {=SEQUENCE(6, 1, 3, 0)} -> 3 | H3: DQ | I3: Don Quixote | J3: 20 | K3: 000 SUM | L3: 2 Star | M3: 150 | N3: 0 | O3: Molar YS | P3: Dieci YS | Q3: YS | R3: Pequod YS | S3: YS | T3: TLA YS | U3: YS | V3: YS | W3: N Fell Bullet YS | X3: Solemn Lament YS | Y3: 4th Match Flame YS | Z3: YS | AA3: YS | AB3: Dimension Shredder YS | AC3: YS | AD3: YS | AE3: 15
A4: =IFERROR(__xludf.DUMMYFUNCTION("""COMPUTED_VALUE"""),3.0) -> 3 | B4: =IFERROR(__xludf.DUMMYFUNCTION("""COMPUTED_VALUE"""),12.0) -> 12 | C4: =B4+C3 -> 22 | D4: 3 | E4: 35 | F4: =F3+G4 -> 66 | G4: 3 | H4: RS | I4: Ryoshu | J4: 113 | K4: =SUM(T2:X2) -> 118 | L4: 000 UT4 | M4: 50 | N4: 150 | R4: LCE YS | T4: Liu YS | W4: BL YS | X4: Heishou YS | Y4: Bygone Days YS | AB4: Crow's Eye View YS | AE4: 5
A5: =IFERROR(__xludf.DUMMYFUNCTION("""COMPUTED_VALUE"""),4.0) -> 4 | B5: =IFERROR(__xludf.DUMMYFUNCTION("""COMPUTED_VALUE"""),15.0) -> 15 | C5: =B5+C4 -> 37 | D5: 4 | E5: 40 | F5: =F4+G5 -> 69 | G5: 3 | H5: MS | I5: Meursault | J5: 16 | K5: {="ID SUM: "& TEXT(K2+K4+12, "???")} -> ID SUM: 181 | L5: ZAYIN | M5: 80 | N5: 110 | O5: FT | P5: Zwei FT | Q5: FT | R5: 7 YS | S5: FT | U5: FT | V5: FT | X5: Index YS | Y5: Fell Bullet YS | Z5: FT | AA5: FT | AB5: Great Trichiliocosm YS | AC5: Command: Meltdown FT | AD5: FT | AE5: 5
A6: =IFERROR(__xludf.DUMMYFUNCTION("""COMPUTED_VALUE"""),5.0) -> 5 | B6: =IFERROR(__xludf.DUMMYFUNCTION("""COMPUTED_VALUE"""),20.0) -> 20 | C6: =B6+C5 -> 57 | D6: 5 | E6: 47 | F6: =F5+G6 -> 72 | G6: 3 | H6: HL | I6: Hong Lu | J6: 215 | K6: =SUM(O2:X2) -> 169 | L6: TETH | M6: 90 | N6: 130 | T6: Regret FT | W6: FT | X6: Ring YS | AB6: Wishing Cairn YS | AE6: 7
A7: =IFERROR(__xludf.DUMMYFUNCTION("""COMPUTED_VALUE"""),6.0) -> 6 | B7: =IFERROR(__xludf.DUMMYFUNCTION("""COMPUTED_VALUE"""),27.0) -> 27 | C7: =B7+C6 -> 84 | D7: 6 | E7: 58 | F7: =F6+G7 -> 75 | G7: 3 | H7: HC | I7: Heathcliff | J7: 57 | K7: EGO SUM | L7: HE | M7: 100 | N7: 150 | O7: DQ | P7: Shi DQ | Q7: DQ | R7: Yuri FT | S7: DQ | T7: Index FT | U7: DQ | V7: DQ | X7: W YS | Y7: Hex Nail FT | Z7: DQ | AA7: DQ | AB7: Sunshower YS | AC7: Yearning-Mircalla DQ | AD7: DQ | AE7: {=(ROUNDUP(SEQUENCE(6,1)/3,0)*2)+9} -> 11
A8: =IFERROR(__xludf.DUMMYFUNCTION("""COMPUTED_VALUE"""),7.0) -> 7 | B8: =IFERROR(__xludf.DUMMYFUNCTION("""COMPUTED_VALUE"""),40.0) -> 40 | C8: =B8+C7 -> 124 | D8: 7 | E8: 69 | F8: =F7+G8 -> 78 | G8: 3 | H8: IS | I8: Ishmael | J8: 299 | K8: =SUM(Y2:AC2) -> 109 | L8: WAW | M8: 150 | N8: 170 | R8: WH FT | T8: Ring FT | W8: Queen of Hatred DQ | Y8: Lasso FT | AE8: 11
A9: =IFERROR(__xludf.DUMMYFUNCTION("""COMPUTED_VALUE"""),8.0) -> 8 | B9: =IFERROR(__xludf.DUMMYFUNCTION("""COMPUTED_VALUE"""),59.0) -> 59 | C9: =B9+C8 -> 183 | D9: 8 | E9: 80 | F9: =F8+G9 -> 80 | G9: {=SEQUENCE(13, 1, 2, 0)} -> 2 | H9: RD | I9: Rodion | J9: 416 | K9: 00 Acquired | L9: None | M9: 0 | N9: 0 | O9: RS | P9: RS | Q9: RS | R9: W FT | S9: RS | T9: MC FT | U9: Chef RS | V9: RS | W9: T DQ | X9: N Fanatic FT | Y9: 9:2 FT | Z9: RS | AA9: RS | AB9: Representation Emitter FT | AC9: Forest for the Flame RS | AD9: RS | AE9: 11
A10: =IFERROR(__xludf.DUMMYFUNCTION("""COMPUTED_VALUE"""),9.0) -> 9 | B10: =IFERROR(__xludf.DUMMYFUNCTION("""COMPUTED_VALUE"""),88.0) -> 88 | C10: =B10+C9 -> 271 | D10: 9 | E10: 93 | F10: =F9+G10 -> 82 | G10: 2 | H10: SC | I10: Sinclair | J10: 61 | K10: =SUM(P2:S2)/SUM(O2:S2) -> 0.92156863 | L10: 3 Star UT | M10: 450 | N10: =150+80+20 -> 250 | T10: Shi FT | U10: KK RS | X10: Heishou FT | AB10: Ardor Blossom Star FT | AE10: 13
A11: =IFERROR(__xludf.DUMMYFUNCTION("""COMPUTED_VALUE"""),10.0) -> 10 | B11: =IFERROR(__xludf.DUMMYFUNCTION("""COMPUTED_VALUE"""),125.0) -> 125 | C11: =B11+C10 -> 396 | D11: 10 | E11: 106 | F11: =F10+G11 -> 84 | G11: 2 | H11: OT | I11: Outis | J11: 135 | K11: 000 Acquired | L11: 00 UT4 | M11: 30 | N11: 100 | O11: MS | P11: RSP MS | Q11: MS | R11: N Fanatic DQ | S11: Middle MS | T11: 7 FT | V11: MS | W11: RS | Y11: Queen of Hatred DQ | Z11: MS | AA11: MS | AB11: Thoracalgia FT | AC11: Crushbound Past MS | AD11: MS | AE11: 13
A12: =IFERROR(__xludf.DUMMYFUNCTION("""COMPUTED_VALUE"""),11.0) -> 11 | B12: =IFERROR(__xludf.DUMMYFUNCTION("""COMPUTED_VALUE"""),168.0) -> 168 | C12: =B12+C11 -> 564 | D12: 11 | E12: 119 | F12: =F11+G12 -> 86 | G12: 2 | H12: GG | I12: Gregor | J12: 97 | K12: =SUM(U2:X2)/SUM(T2:X2) -> 0.58474576 | L12: 2 3 Star | M12: 800 | N12: 0 | P12: WH MS | R12: Lantern DQ | U12: MS | Y12: Electric Screaming DQ | AB12: Everlasting FT | AE12: 13
A13: =IFERROR(__xludf.DUMMYFUNCTION("""COMPUTED_VALUE"""),12.0) -> 12 | B13: =IFERROR(__xludf.DUMMYFUNCTION("""COMPUTED_VALUE"""),227.0) -> 227 | C13: =B13+C12 -> 791 | D13: 12 | E13: 136 | F13: =F12+G13 -> 88 | G13: 2 | I13: Crate | J13: 2493 | K13: ID Acquired | L13: {="2 Star UT" & SEQUENCE(3,1)} -> 2 Star UT1 | M13: =P2 -> 8 | O13: HL | Q13: HL | R13: BL DQ | S13: HL | T13: Cinq S DQ | V13: HL | W13: W MS | X13: LCE FT | Y13: Lifetime Stew DQ | Z13: HL | AA13: HL | AB13: Fluid Sac FT | AC13: Cavernous Wailing HL | AD13: HL | AE13: {=(ROUNDUP(SEQUENCE(6,1)/3,0)*2)+15} -> 17
A14: =IFERROR(__xludf.DUMMYFUNCTION("""COMPUTED_VALUE"""),13.0) -> 13 | B14: =IFERROR(__xludf.DUMMYFUNCTION("""COMPUTED_VALUE"""),298.0) -> 298 | C14: =B14+C13 -> 1089 | D14: 13 | E14: 153 | F14: =F13+G14 -> 90 | G14: 2 | I14: Pass | J14: 1201 | K14: =(SUM(P2:S2)+SUM(U2:X2))/SUM(O2:X2) -> 0.68639053 | L14: 2 Star UT2 | M14: =Q2 -> 1 | P14: HL | T14: Cinq E DQ | U14: HL | X14: BL FT | Y14: Fluid Sac DQ | AB14: Telepole FT | AC14: To Remain Oneself HL | AE14: 17
A15: =IFERROR(__xludf.DUMMYFUNCTION("""COMPUTED_VALUE"""),14.0) -> 14 | B15: =IFERROR(__xludf.DUMMYFUNCTION("""COMPUTED_VALUE"""),381.0) -> 381 | C15: =B15+C14 -> 1470 | D15: 14 | E15: 170 | F15: =F14+G15 -> 92 | G15: 2 | I15: Threads | J15: 3925 | K15: EGO Acquired | L15: 2 Star UT3 | M15: =R2 -> 36 | O15: HC | Q15: HC | R15: LCCB RS | S15: MC HC | T15: W DQ | V15: HC | W15: Tingtang HL | Y15: Telepole DQ | Z15: HC | AA15: HC | AC15: Tarnished Blood HL | AD15: HC | AE15: 17
A16: =IFERROR(__xludf.DUMMYFUNCTION("""COMPUTED_VALUE"""),15.0) -> 15 | B16: =IFERROR(__xludf.DUMMYFUNCTION("""COMPUTED_VALUE"""),482.0) -> 482 | C16: =B16+C15 -> 1952 | D16: 15 | E16: 189 | F16: =F15+G16 -> 94 | G16: 2 | K16: =SUM(Z2:AC2)/SUM(Y2:AC2) -> 0.49541284 | L16: {="3 Star UT" & SEQUENCE(3,1)} -> 3 Star UT1 | M16: =U2 -> 2 | P16: HC | R16: D20 RS | U16: HC | W16: S Corp HL | X16: Manager DQ | AB16: La Sangre de Sancho DQ | AE16: 19
A17: =IFERROR(__xludf.DUMMYFUNCTION("""COMPUTED_VALUE"""),16.0) -> 16 | B17: =IFERROR(__xludf.DUMMYFUNCTION("""COMPUTED_VALUE"""),591.0) -> 591 | C17: =B17+C16 -> 2543 | D17: 16 | E17: 208 | F17: =F16+G17 -> 96 | G17: 2 | H17: 00 | I17: Daily | J17: 1 | K17: 00 Leftover | L17: 3 Star UT2 | M17: =V2 -> 0 | O17: IS | Q17: TLA IS | R17: Liu RS | S17: IS | T17: RE&P RS | V17: IS | W17: FS HL | X17: Heishou DQ | Y17: Contempt, Awe RS | Z17: IS | AA17: IS | AB17: Wishing Cairn DQ | AC17: HC | AD17: IS | AE17: 19
A18: =IFERROR(__xludf.DUMMYFUNCTION("""COMPUTED_VALUE"""),17.0) -> 17 | B18: =IFERROR(__xludf.DUMMYFUNCTION("""COMPUTED_VALUE"""),728.0) -> 728 | C18: =B18+C17 -> 3271 | D18: 17 | E18: 227 | F18: =F17+G18 -> 98 | G18: 2 | H18: =K10 -> 0.92156863 | I18: Dailyx7 | J18: 7 | K18: =O2/SUM(O2:S2) -> 0.078431373 | L18: 3 Star UT3 | M18: =W2 -> 19 | P18: IS | R18: 7 RS | T18: Araya RS | U18: IS | W18: R HL | X18: Middle DQ | Y18: Red Eyes (Open) RS | AB18: Red Sheet DQ | AE18: 19
A19: =IFERROR(__xludf.DUMMYFUNCTION("""COMPUTED_VALUE"""),18.0) -> 18 | B19: =IFERROR(__xludf.DUMMYFUNCTION("""COMPUTED_VALUE"""),885.0) -> 885 | C19: =B19+C18 -> 4156 | D19: 18 | E19: 250 | F19: =F18+G19 -> 100 | G19: 2 | H19: 000 | I19: Weekly | J19: 2 | K19: 000 Leftover | O19: RD | Q19: RD | S19: RD | T19: WH RS | V19: RD | W19: K HL | X19: Index DQ | Y19: 4th Match Flame RS | Z19: RD | AA19: RD | AC19: IS | AD19: RD | AE19: {=(ROUNDUP(SEQUENCE(3,1)/3,0)*2)+21} -> 23
A20: =IFERROR(__xludf.DUMMYFUNCTION("""COMPUTED_VALUE"""),19.0) -> 19 | B20: =IFERROR(__xludf.DUMMYFUNCTION("""COMPUTED_VALUE"""),1064.0) -> 1064 | C20: =B20+C19 -> 5220 | D20: 19 | E20: 273 | F20: =F19+G20 -> 102 | G20: 2 | H20: =K12 -> 0.58474576 | I20: 3WeeklyHardTotal | J20: 25 | K20: =T2/SUM(T2:X2) -> 0.41525424 | L20: UT3 Lunacy | M20: =(SUM(M13:M17)-M15)*40 -> 440 | P20: N Fanatic RD | R20: Liu MS | T20: W RS | U20: RD | Y20: Blind Obsession RS | AB20: Great Trichiliocosm RS | AE20: 23
A21: =IFERROR(__xludf.DUMMYFUNCTION("""COMPUTED_VALUE"""),20.0) -> 20 | B21: =IFERROR(__xludf.DUMMYFUNCTION("""COMPUTED_VALUE"""),1261.0) -> 1261 | C21: =B21+C20 -> 6481 | D21: 20 | E21: 296 | F21: =F20+G21 -> 104 | G21: 2 | H21: ID | I21: 1stWeekly | J21: 7.5 | K21: ID Leftover | L21: 2 Star UT3 | M21: =(M13*10)+((M14+M13)*40) -> 440 | O21: Molar SC | P21: Zwei RD | Q21: SC | S21: SC | V21: SC | W21: HC | X21: N Contempt, Awe RS | Y21: Red Eyes RS | Z21: SC | AA21: SC | AB21: Thoracalgia RS | AC21: RD | AD21: SC | AE21: 23
A22: =IFERROR(__xludf.DUMMYFUNCTION("""COMPUTED_VALUE"""),21.0) -> 21 | B22: =IFERROR(__xludf.DUMMYFUNCTION("""COMPUTED_VALUE"""),1488.0) -> 1488 | C22: =B22+C21 -> 7969 | D22: 21 | E22: 326 | F22: =F21+G22 -> 105 | G22: {=SEQUENCE(21, 1, 1, 0)} -> 1 | H22: =K14 -> 0.68639053 | I22: 2ndWeekly | J22: 8 | K22: =(O2+T2)/SUM(O2:X2) -> 0.31360947 | L22: 3 Star UT3 | M22: =(M16*20)+((M17+M16)*80) -> 200 | R22: Fanghunt HL | T22: N Fanatic MS | U22: SC | X22: Heishou RS | Y22: Soda RS | AE22: {=(ROUNDUP(SEQUENCE(12,1)/3,0)*2)+28} -> 30
A23: =IFERROR(__xludf.DUMMYFUNCTION("""COMPUTED_VALUE"""),22.0) -> 22 | B23: =IFERROR(__xludf.DUMMYFUNCTION("""COMPUTED_VALUE"""),1739.0) -> 1739 | C23: =B23+C22 -> 9708 | D23: 22 | E23: 356 | F23: =F22+G23 -> 106 | G23: 1 | H23: EGO | I23: 3rdWeekly | J23: 9.5 | K23: EGO Leftover | L23: 2 Star UT4 | M23: =(SUM(M13:M15))*100 -> 4500 | O23: OT | P23: Zwei S SC | Q23: OT | R23: Hook HL | S23: OT | T23: Dieci MS | V23: OT | W23: Molar IS | Z23: OT | AA23: OT | AC23: SC | AD23: OT | AE23: 30
A24: =IFERROR(__xludf.DUMMYFUNCTION("""COMPUTED_VALUE"""),23.0) -> 23 | B24: =IFERROR(__xludf.DUMMYFUNCTION("""COMPUTED_VALUE"""),2016.0) -> 2016 | C24: =B24+C23 -> 11724 | D24: 23 | E24: 386 | F24: =F23+G24 -> 107 | G24: 1 | H24: =K16 -> 0.49541284 | I24: 3WeeklyOnce | J24: 22.5 | K24: =Y2/SUM(Y2:AC2) -> 0.50458716 | L24: 3 Star UT4 | M24: =(SUM(M16:M18))*150 -> 3150 | R24: KK HL | T24: R MS | U24: OT | W24: Liu IS | X24: Daiyu RS | Y24: Screwloose Wallop MS | AB24: Chains of Others MS | AE24: 30
A25: =IFERROR(__xludf.DUMMYFUNCTION("""COMPUTED_VALUE"""),24.0) -> 24 | B25: =IFERROR(__xludf.DUMMYFUNCTION("""COMPUTED_VALUE"""),2327.0) -> 2327 | C25: =B25+C24 -> 14051 | D25: 24 | E25: 418 | F25: =F24+G25 -> 108 | G25: 1 | I25: MostWeekly | J25: =J20+J19+J18 -> 34 | O25: Chef GG | P25: OT | Q25: GG | R25: Liu HL | S25: GG | V25: GG | X25: FA&S RS | Y25: Shadow-Vested Bladesinger MS | Z25: GG | AA25: GG | AB25: Regret MS | AC25: OT | AD25: GG | AE25: 32
A26: =IFERROR(__xludf.DUMMYFUNCTION("""COMPUTED_VALUE"""),25.0) -> 25 | B26: =IFERROR(__xludf.DUMMYFUNCTION("""COMPUTED_VALUE"""),2674.0) -> 2674 | C26: =B26+C25 -> 16725 | D26: 25 | E26: 450 | F26: =F25+G26 -> 109 | G26: 1 | L26: All UT3 Threads | M26: =M21+M22 -> 640 | O26: KK GG | R26: W HL | T26: Dieci HL | U26: GG | Y26: Yearning-Mircalla MS | AE26: 32
A27: =IFERROR(__xludf.DUMMYFUNCTION("""COMPUTED_VALUE"""),26.0) -> 26 | B27: =IFERROR(__xludf.DUMMYFUNCTION("""COMPUTED_VALUE"""),3047.0) -> 3047 | C27: =B27+C26 -> 19772 | D27: 26 | E27: 482 | F27: =F26+G27 -> 110 | G27: 1 | I27: Skip Thread 5 | J27: 18 | L27: All UT4 Threads | M27: =SUM(M21:M24) -> 8290 | P27: GG | W27: Dieci RD | X27: Thumb MS | Y27: Electric Screaming MS | AB27: Land of Illusion HL | AC27: Unbrilliant Glory GG | AE27: 32
A28: =IFERROR(__xludf.DUMMYFUNCTION("""COMPUTED_VALUE"""),27.0) -> 27 | B28: =IFERROR(__xludf.DUMMYFUNCTION("""COMPUTED_VALUE"""),3456.0) -> 3456 | C28: =B28+C27 -> 23228 | D28: 27 | E28: 516 | F28: =F27+G28 -> 111 | G28: 1 | I28: Daily Threads | J28: =J27*3 -> 54 | L28: Threads Needed | M28: =MAX(0, M27-J15) -> 4365 | R28: N Fanatic HC | T28: Pequod HC | W28: KK RD | X28: Hornet MS | Y28: Pursuance MS | AE28: 34
A29: =IFERROR(__xludf.DUMMYFUNCTION("""COMPUTED_VALUE"""),28.0) -> 28 | B29: =IFERROR(__xludf.DUMMYFUNCTION("""COMPUTED_VALUE"""),3899.0) -> 3899 | C29: =B29+C28 -> 27127 | D29: 28 | E29: 550 | F29: =F28+G29 -> 112 | G29: 1 | R29: Shi HC | T29: Thumb HC | W29: Liu RD | X29: Prince MS | Y29: Capote MS | AB29: Asymmetrical Inertia HC | AE29: 34
A30: =IFERROR(__xludf.DUMMYFUNCTION("""COMPUTED_VALUE"""),29.0) -> 29 | B30: =IFERROR(__xludf.DUMMYFUNCTION("""COMPUTED_VALUE"""),4378.0) -> 4378 | C30: =B30+C29 -> 31505 | D30: 29 | E30: 584 | F30: =F29+G30 -> 113 | G30: 1 | H30: 0 | I30: {="Ticket " & ROMAN(SEQUENCE(4,1))} -> Ticket I | J30: 52 | K30: 50 | L30: Days Needed | M30: =MAX(0, ROUNDUP((M28-J15)/J28,0)) -> 9 | N30: {=ROUNDDOWN((J30:J33*K30:K33)/($K$33),0)} -> 0 | R30: 7 HC | T30: Oufi HC | X30: Ring MS | AB30: Move-in Reg. HC | AE30: 34
A31: =IFERROR(__xludf.DUMMYFUNCTION("""COMPUTED_VALUE"""),30.0) -> 30 | B31: =IFERROR(__xludf.DUMMYFUNCTION("""COMPUTED_VALUE"""),4899.0) -> 4899 | C31: =B31+C30 -> 36404 | D31: 30 | E31: 620 | F31: =F30+G31 -> 114 | G31: 1 | H31: 6 | I31: Ticket II | J31: 286 | K31: 200 | L31: for UT3 | M31: =MAX(0, ROUNDUP((M26-J15)/J28,0)) -> 0 | N31: 19 | T31: TLA HC | W31: N Fanatic SC | X31: Cinq MS | Y31: Dimension Shredder HL | AB31: Fell Bullet HC | AE31: 36
A32: =IFERROR(__xludf.DUMMYFUNCTION("""COMPUTED_VALUE"""),31.0) -> 31 | B32: =IFERROR(__xludf.DUMMYFUNCTION("""COMPUTED_VALUE"""),3899.0) -> 3899 | C32: =B32+C31 -> 40303 | D32: 31 | E32: 656 | F32: =F31+G32 -> 115 | G32: 1 | H32: 6 | I32: Ticket III | J32: 298 | K32: 1000 | L32: for TS3 | M32: =MAX(0, ROUNDUP((J51-J15)/J28,0)) -> 0 | N32: 99 | R32: LCCB IS | T32: KK HC | W32: Dawn SC | X32: BL MS | Y32: Effervescent Corrosion HL | AB32: Bodysack HC | AE32: 36
A33: =IFERROR(__xludf.DUMMYFUNCTION("""COMPUTED_VALUE"""),32.0) -> 32 | B33: =IFERROR(__xludf.DUMMYFUNCTION("""COMPUTED_VALUE"""),4378.0) -> 4378 | C33: =B33+C32 -> 44681 | D33: 32 | E33: 692 | F33: =F32+G33 -> 116 | G33: 1 | H33: 6 | I33: Ticket IV | J33: 287 | K33: 3000 | L33: for TS4 | M33: =MAX(0, ROUNDUP((J45-J15)/J28,0)) -> 53 | N33: 287 | R33: WH IS | T33: FS HC | Y33: Roseate Desire HL | AB33: Binds HC | AE33: 36
A34: =IFERROR(__xludf.DUMMYFUNCTION("""COMPUTED_VALUE"""),33.0) -> 33 | B34: =IFERROR(__xludf.DUMMYFUNCTION("""COMPUTED_VALUE"""),4899.0) -> 4899 | C34: =B34+C33 -> 49580 | D34: 33 | E34: 736 | F34: =F33+G34 -> 117 | G34: 1 | L34: Total Ticket IV Amount | N34: =SUM(N30:N33) -> 405 | R34: Shi IS | T34: R HC | W34: Udjat OT | X34: Ring HL | Y34: Lasso HL | AE34: {=(ROUNDUP(SEQUENCE(3,1)/3,0)*2)+42} -> 44
A35: =IFERROR(__xludf.DUMMYFUNCTION("""COMPUTED_VALUE"""),34.0) -> 34 | B35: =IFERROR(__xludf.DUMMYFUNCTION("""COMPUTED_VALUE"""),5468.0) -> 5468 | C35: =B35+C34 -> 55048 | D35: 34 | E35: 780 | F35: =F34+G35 -> 118 | G35: 1 | I35: XP Lux | J35: 60 | L35: Max Acc Acq | M35: =MAX(0, ROUNDUP((M28+J45-J15)/J28,0)) -> 134 | X35: Lord HL | Y35: Soda HL | AB35: Hundred-Footed Death Maggot IS | AE35: 44
A36: =IFERROR(__xludf.DUMMYFUNCTION("""COMPUTED_VALUE"""),35.0) -> 35 | B36: =IFERROR(__xludf.DUMMYFUNCTION("""COMPUTED_VALUE"""),6075.0) -> 6075 | C36: =B36+C35 -> 61123 | D36: 35 | E36: 824 | F36: =F35+G36 -> 119 | G36: 1 | I36: XP Lux Skip | J36: 90 | R36: LCCB RD | T36: Pequod IS | W36: G GG | X36: D20 HL | AB36: Christmas Nightmare IS | AE36: 44
A37: =IFERROR(__xludf.DUMMYFUNCTION("""COMPUTED_VALUE"""),36.0) -> 36 | B37: =IFERROR(__xludf.DUMMYFUNCTION("""COMPUTED_VALUE"""),4899.0) -> 4899 | C37: =B37+C36 -> 66022 | D37: 36 | E37: 871 | F37: =F36+G37 -> 120 | G37: 1 | I37: Thread Lux | J37: 40 | R37: T RD | T37: Zwei IS | Y37: Ya Śūnyatā Tad Rūpam HC | AB37: Ardor Blossom Star IS | AE37: {=(ROUNDUP(SEQUENCE(9,1)/3,0)*2)+45} -> 47
A38: =IFERROR(__xludf.DUMMYFUNCTION("""COMPUTED_VALUE"""),37.0) -> 37 | B38: =IFERROR(__xludf.DUMMYFUNCTION("""COMPUTED_VALUE"""),5468.0) -> 5468 | C38: =B38+C37 -> 71490 | D38: 37 | E38: 918 | F38: =F37+G38 -> 121 | G38: 1 | I38: Thread Lux Skip | J38: 60 | T38: KK IS | X38: Heishou HC | Y38: Telepole HC | AB38: Blind Obsession IS | AE38: 47
A39: =IFERROR(__xludf.DUMMYFUNCTION("""COMPUTED_VALUE"""),38.0) -> 38 | B39: =IFERROR(__xludf.DUMMYFUNCTION("""COMPUTED_VALUE"""),6075.0) -> 6075 | C39: =B39+C38 -> 77565 | D39: 38 | E39: 965 | F39: =F38+G39 -> 122 | G39: 1 | I39: Daily Manager XP | J39: =(J38*3)+J35 -> 240 | R39: Mariachi SC | T39: R IS | X39: Middle HC | Y39: Holiday HC | AB39: Snagharpoon IS | AE39: 47
A40: =IFERROR(__xludf.DUMMYFUNCTION("""COMPUTED_VALUE"""),39.0) -> 39 | B40: =IFERROR(__xludf.DUMMYFUNCTION("""COMPUTED_VALUE"""),6722.0) -> 6722 | C40: =B40+C39 -> 84287 | D40: 39 | E40: 1014 | F40: =F39+G40 -> 123 | G40: 1 | R40: Zwei W SC | Y40: AEDD HC | AB40: Tidal Elegy IS | AE40: 49
...

Sheet IF SS7 Sheet
A1: Sinner | B1: ID #1 | C1: ID #2 | D1: EGO | F1: Actual Result | G1: ID #1 | H1: ID #2 | I1: ID #3 | J1: EGO | K1: EGO #2 | L1: Keyword for | M1: ID #1 | N1: ID #2 | O1: ID #3 | P1: EGO | Q1: EGO #2
A2: Yi Sang | C2: Dimension Shredder | D2: ? Walp X | F2: Yi Sang | G2: Index Father | J2: WAW BP | K2: SL Walp IX | L2: Yi Sang | M2: Poise Burn Sinking | P2: Poise Burn Sinking | Q2: Sinking
A3: Faust | B3: ? Walp X | C3: Hex Nail | F3: Faust | G3: Index Proselyte | H3: Ring Apprentice | I3: Yuna Walp IX | J3: Ardor Blossom Bkgk | L3: Faust | M3: Poise Sinking | N3: Charge Bleed | O3: Burn | P3: Burn
A4: Don Quixote | F4: Don Quixote | G4: Index Apprentice | L4: Don Quixote | M4: Poise Sinking
A5: Ryoshu | F5: Ryoshu | G5: FA&S Walp VIII | H5: Pinky Araya | J5: WAW BP | L5: Ryoshu | M5: Tremor Sinking | N5: Poise Burn Bleed | P5: Poise Burn Bleed
A6: Meursault | B6: Night Drifter | C6: Bad End | D6: WAW BP | F6: Meursault | G6: Hornet Walp VIII | H6: Ring Student Intv | J6: Shadow-Vested Intv2 | L6: Meursault | M6: Burn Bleed | N6: Sinking Bleed | P6: Poise Bleed
A7: Hong Lu | C7: Carvenous Wailings | F7: Hong Lu | G7: Ring Father | H7: S Corp Intv2 | L7: Hong Lu | M7: Charge Burn Bleed | N7: Poise Bleed
A8: Heathcliff | C8: King of Binds | D8: ZAYIN BP | F8: Heathcliff | G8: Middle Ricardo Bkgk2 | H8: Thumb Apprentice | J8: TETH BP | L8: Heathcliff | M8: Burn Bleed | N8: Burn Tremor | P8: Charge Burn
A9: Ishmael | C9: Blind Obsession | D9: WAW BP | F9: Ishmael | G9: Middle Apprentice | H9: LCD Osir Intv2 | L9: Ishmael | M9: Burn Bleed | N9: Poise Bleed
A10: Rodion | C10: Indicant's Trial | F10: Rodion | G10: Ring Docent Intv | H10: Thumb Father | J10: Into the Sunset Bkgk2 | L10: Rodion | M10: Sinking Bleed | N10: Burn Tremor | P10: Burn Bleed
A11: Sinclair | C11: Lantern | F11: Sinclair | G11: Pinky Apprentice | H11: Wayfarer SF | J11: Harmony Walp VIII | L11: Sinclair | M11: Poise Bleed | N11: Tremor Charge | P11: Burn Bleed
A12: Outis | B12: ? Walp X | F12: Outis | G12: Udjat Leader | H12: Middle Father | J12: ZAYIN BP | L12: Outis | M12: Tremor Sinking | N12: Burn Bleed | P12: Bleed
A13: Gregor | D13: HE BP | F13: Gregor | G13: Lobo Lamp | H13: LCE AEDD Bkgk | I13: Salvador Walp IX | L13: Gregor | M13: Burn Sinking | N13: Charge Rupture | O13: Burn
A15: Thumb | B15: =COUNTIF(B2:C13, "*Thumb*") -> 0 | F15: Thumb | G15: =COUNTIF(G2:I13, "*Thumb*") -> 2 | H15: Non-Finger IDs | I15: =IFERROR(__xludf.DUMMYFUNCTION("COUNTA(G2:I13) - ARRAYFORMULA(SUM(N(REGEXMATCH(G2:I13, ""Thumb|Index|Middle|Ring|Pinky""))))"),10.0) -> 10 | L15: Burn | M15: {=MAP(L15:L21, LAMBDA(row, IF(row<>"", "ID: " & COUNTIF(M2:O13, "*"&row&"*") & ", EGO: " & COUNTIF(P2:Q13, "*"&row&"*"), )))} -> ID: 12, EGO: 6 | N15: Poise Rupture | O15: Charge Rupture | P15: Rupture Sinking
A16: Index | B16: =COUNTIF(B2:C13, "*Index*") -> 0 | F16: Index | G16: =COUNTIF(G2:I13, "*Index*") -> 3 | H16: Non-BP EGOs | I16: =IFERROR(__xludf.DUMMYFUNCTION("COUNTA(J2:K13) - ARRAYFORMULA(SUM(N(REGEXMATCH(J2:K13, "" BP""))))"),5.0) -> 5 | L16: Bleed | M16: ID: 12, EGO: 5 | N16: Burn Bleed | O16: Poise Charge | P16: Poise Sinking
A17: Middle | B17: =COUNTIF(B2:C13, "*Middle*") -> 0 | F17: Middle | G17: =COUNTIF(G2:I13, "*Middle*") -> 3 | H17: House of Spiders | I17: =IFERROR(__xludf.DUMMYFUNCTION("ARRAYFORMULA(SUM(N(REGEXMATCH(G2:I13, ""Father|Apprentice|App|Araya""))))"),10.0) -> 10 | L17: Tremor | M17: ID: 5, EGO: 0 | N17: Sinking Bleed | O17: Tremor Burn | P17: Charge Sinking
A18: Ring | B18: =COUNTIF(B2:C13, "*Ring*") -> 0 | F18: Ring | G18: =COUNTIF(G2:I13, "*Ring*") -> 4 | H18: Total IDs | I18: =COUNTA(G2:I13) -> 24 | L18: Rupture | M18: ID: 1, EGO: 0 | N18: Tremor Bleed | O18: Tremor Sinking | P18: Burn Sinking
A19: Pinky | B19: =COUNTIF(B2:C13, "*Pinky*") -> 0 | F19: Pinky | G19: =COUNTIF(G2:I13, "*Pinky*") -> 2 | H19: Total EGOs | I19: =COUNTA(J2:K13) -> 9 | L19: Sinking | M19: ID: 8, EGO: 2 | N19: Rupture Bleed | O19: Tremor Rupture | P19: Burn Rupture
F20: Walpurgisnaughts | G20: =COUNTIF(G2:K13, "* Walp*") -> 6 | H20: No Faction Stuff | I20: =IFERROR(__xludf.DUMMYFUNCTION("COUNTA(G2:K13) - ARRAYFORMULA(SUM(N(REGEXMATCH(G2:K13, ""Thumb|Index|Middle|Ring|Pinky| Walp| Intv| Bkgk| BP""))))"),3.0) -> 3 | L20: Poise | M20: ID: 7, EGO: 3 | N20: Charge Bleed | O20: Tremor Charge | P20: Charge Burn
F21: Intervallos & Bokgaks | G21: =COUNTIF(G2:K13, "* Intv*") + COUNTIF(G2:K13, "* Bkgk") -> 7 | H21: Standard Fare | I21: =COUNTIF(G2:K13, "* SF*") -> 1 | L21: Charge | M21: ID: 4, EGO: 1 | N21: Poise Bleed | O21: Poise Tremor | P21: Poise Burn
A23: Burn | G23: Burn | H23: Tremor
A24: Liu YS | B24: LCE FT | C24: Cinq E DQ | D24: Araya RS | E24: Hornet MS | F24: Liu HL | G24: Liu YS | H24: LCE FT | I24: T DQ | J24: FA&S RS | K24: Thumb MS | L24: D20 HL
A25: Heishou HC | B25: Liu IS | C25: Liu RD | D25: Dawn SC | E25: Magic Bullet OT | F25: Firefist GG | G25: Thumb HC | H25: Hanafuda IS | I25: Thumb RD | J25: Thumb SC | K25: Magic Bullet OT | L25: Firefist GG
A26: Bleed | G26: Bleed | H26: Tremor
A27: Ring YS | B27: Ring FT | C27: Mancha DQ | D27: Awe RS | E27: Mancha MS | F27: Ring HL | G27: Ring YS | H27: Ring FT | I27: Mancha DQ | J27: Awe RS | K27: Mancha MS | L27: Ring HL
A28: KK HC | B28: KK IS | C28: Mancha RD | D28: Pinky SC | E28: Mancha OT | F28: Priest GG | G28: KK HC | H28: KK IS | I28: Mancha RD | J28: Thumb SC | K28: T OT | L28: Night Awl GG
A29: Tremor | G29: Tremor Souls | H29: Sinking | I29: Burn | J29: Bleed
A30: Heishou YS | B30: Regret FT | C30: T DQ | D30: Awe RS | E30: Thumb MS | F30: D20 HL | G30: Heishou YS | H30: Regret FT | I30: T DQ | J30: FA&S RS | K30: Thumb MS | L30: D20 HL
A31: Oufi HC | B31: Zwei IS | C31: T RD | D31: Thumb SC | E31: T OT | F31: Night Awl GG | G31: Thumb HC | H31: Hanafuda IS | I31: Thumb RD | J31: Thumb SC | K31: Udjat OT | L31: Night Awl GG
A32: Rupture | G32: Heishou | H32: Poise | I32: Rupture
A33: LCE YS | B33: Heishou FT | C33: Lantern DQ | D33: Heishou RS | E33: Cinq MS | F33: Lord HL | G33: Heishou YS | H33: Heishou FT | I33: Heishou DQ | J33: Daiyu RS | K33: Cinq MS | L33: Lord HL
A34: 7 HC | B34: Xichun IS | C34: Devyat RD | D34: Devyat SC | E34: Heishou OT | F34: AEDD GG | G34: Heishou HC | H34: Xichun IS | I34: Heishou RD | J34: Heishou SC | K34: Heishou OT | L34: Heishou GG
A35: Sinking | G35: Sinking Hybrid | H35: Tremor | I35: Poise
A36: TLA YS | B36: WH FT | C36: Heishou DQ | D36: FA&S RS | E36: Dieci MS | F36: R HL | G36: Solemn Lament YS | H36: Index FT | I36: Index DQ | J36: FA&S RS | K36: Dieci MS | L36: Dieci HL
A37: WH HC | B37: Molar IS | C37: KoD RD | D37: Mariachi SC | E37: WH OT | F37: WH GG | G37: WH HC | H37: Hanafuda IS | I37: KoD RD | J37: Mariachi SC | K37: Udjat OT | L37: Lamp GG
A38: Poise | G38: Poise | H38: Sinking
A39: Index YS | B39: Index FT | C39: Index DQ | D39: Daiyu RS | E39: BL MS | F39: FS HL | G39: Index YS | H39: Index FT | I39: Index DQ | J39: FA&S RS | K39: Cinq MS | L39: FS HL
A40: FS HC | B40: WH IS | C40: Heishou RD | D40: Pinky SC | E40: Cinq OT | F40: Heishou GG | G40: FS HC | H40: Hanafuda IS | I40: KoD RD | J40: Pinky/Yan SC | K40: WH OT | L40: WH/Lamp GG
A41: Charge | G41: Charge | H41: Bleed
A42: W YS | B42: MC FT | C42: W DQ | D42: RE&P RS | E42: R MS | F42: R HL | G42: Ring YS | H42: Ring FT | I42: W DQ | J42: RE&P RS | K42: Ring MS | L42: Ring HL
...

Sheet IF SS8 Sheet
A1: Sinner | B1: ID #1 | C1: ID #2 | D1: EGO | F1: Actual Result | G1: ID #1 | H1: ID #2 | I1: ID #3 | J1: EGO | K1: EGO #2 | L1: Keyword for | M1: ID #1 | N1: ID #2 | O1: ID #3 | P1: EGO | Q1: EGO #2
A2: Yi Sang | C2: Dimension Shredder | D2: ? Walp X | F2: Yi Sang | G2: Dim Shred NC EG | J2: ? Walp X | L2: Yi Sang | M2: Charge Rupture
A3: Faust | B3: ? Walp X | C3: Hex Nail | F3: Faust | G3: ? Walp X | H3: Hex Nail NC EG | L3: Faust | N3: Bleed
A4: Don Quixote | F4: Don Quixote | L4: Don Quixote
A5: Ryoshu | F5: Ryoshu | L5: Ryoshu
A6: Meursault | B6: Night Drifter | C6: Bad End | D6: WAW BP | F6: Meursault | G6: Night Drifter Bkgk | H6: Bad End | J6: WAW BP | L6: Meursault | M6: Poise Bleed
A7: Hong Lu | C7: Carvenous Wailings | F7: Hong Lu | G7: Carv Wails NC EG | L7: Hong Lu | M7: Tremor
A8: Heathcliff | C8: King of Binds | D8: ZAYIN BP | F8: Heathcliff | G8: Binds NC EG | J8: ZAYIN BP | L8: Heathcliff | M8: Tremor Sinking
A9: Ishmael | C9: Blind Obsession | D9: WAW BP | F9: Ishmael | G9: Blind Obsess NC EG | J9: WAW BP | L9: Ishmael | M9: Poise Charge Rupture
A10: Rodion | C10: Indicant's Trial | F10: Rodion | G10: Indicant's NC EG | L10: Rodion | M10: Burn
A11: Sinclair | C11: Lantern | F11: Sinclair | G11: Lantern NC EG | L11: Sinclair | M11: Rupture
A12: Outis | B12: ? Walp X | F12: Outis | G12: ? Walp X | L12: Outis
A13: Gregor | D13: HE BP | F13: Gregor | J13: HE BP | L13: Gregor
A15: Thumb | B15: =COUNTIF(B2:C13, "*Thumb*") -> 0 | F15: E.G.O Gear | G15: =COUNTIF(G2:I13, "* EG*") -> 7 | H15: Non-Finger IDs | I15: =IFERROR(__xludf.DUMMYFUNCTION("COUNTA(G2:I13) - ARRAYFORMULA(SUM(N(REGEXMATCH(G2:I13, ""Thumb|Index|Middle|Ring|Pinky""))))"),11.0) -> 11 | L15: Burn | M15: {=MAP(L15:L21, LAMBDA(row, IF(row<>"", "ID: " & COUNTIF(M2:O13, "*"&row&"*") & ", EGO: " & COUNTIF(P2:Q13, "*"&row&"*"), )))} -> ID: 1, EGO: 0 | N15: Poise Rupture | O15: Charge Rupture | P15: Rupture Sinking
A16: Index | B16: =COUNTIF(B2:C13, "*Index*") -> 0 | F16: E.G.O Gear | G16: =COUNTIF(G2:I13, "* EG*") -> 7 | H16: Non-BP EGOs | I16: =IFERROR(__xludf.DUMMYFUNCTION("COUNTA(J2:K13) - ARRAYFORMULA(SUM(N(REGEXMATCH(J2:K13, "" BP""))))"),1.0) -> 1 | L16: Bleed | M16: ID: 2, EGO: 0 | N16: Burn Bleed | O16: Poise Charge | P16: Poise Sinking
A17: Middle | B17: =COUNTIF(B2:C13, "*Middle*") -> 0 | F17: Middle | G17: =COUNTIF(G2:I13, "*Middle*") -> 0 | H17: N Corp | I17: =COUNTIF(G2:I13, "* NC*") -> 7 | L17: Tremor | M17: ID: 2, EGO: 0 | N17: Sinking Bleed | O17: Tremor Burn | P17: Charge Sinking
A18: Ring | B18: =COUNTIF(B2:C13, "*Ring*") -> 0 | F18: Ring | G18: =COUNTIF(G2:I13, "*Ring*") -> 0 | H18: Total IDs | I18: =COUNTA(G2:I13) -> 11 | L18: Rupture | M18: ID: 3, EGO: 0 | N18: Tremor Bleed | O18: Tremor Sinking | P18: Burn Sinking
A19: Pinky | B19: =COUNTIF(B2:C13, "*Pinky*") -> 0 | F19: Pinky | G19: =COUNTIF(G2:I13, "*Pinky*") -> 0 | H19: Total EGOs | I19: =COUNTA(J2:K13) -> 5 | L19: Sinking | M19: ID: 1, EGO: 0 | N19: Rupture Bleed | O19: Tremor Rupture | P19: Burn Rupture
F20: Walpurgisnaughts | G20: =COUNTIF(G2:K13, "* Walp*") -> 3 | H20: No Faction Stuff | I20: =IFERROR(__xludf.DUMMYFUNCTION("COUNTA(G2:K13) - ARRAYFORMULA(SUM(N(REGEXMATCH(G2:K13, ""Thumb|Index|Middle|Ring|Pinky| Walp| Intv| Bkgk| BP""))))"),8.0) -> 8 | L20: Poise | M20: ID: 2, EGO: 0 | N20: Charge Bleed | O20: Tremor Charge | P20: Charge Burn
F21: Intervallos & Bokgaks | G21: =COUNTIF(G2:K13, "* Intv*") + COUNTIF(G2:K13, "* Bkgk") -> 1 | H21: Standard Fare | I21: =COUNTIF(G2:K13, "* SF*") -> 0 | L21: Charge | M21: ID: 2, EGO: 0 | N21: Poise Bleed | O21: Poise Tremor | P21: Poise Burn
A23: Burn | G23: Burn | H23: Tremor
A24: Liu YS | B24: LCE FT | C24: Cinq E DQ | D24: Araya RS | E24: Hornet MS | F24: Liu HL | G24: Liu YS | H24: LCE FT | I24: T DQ | J24: FA&S RS | K24: Thumb MS | L24: D20 HL
A25: Heishou HC | B25: Liu IS | C25: Liu RD | D25: Dawn SC | E25: Magic Bullet OT | F25: Firefist GG | G25: Thumb HC | H25: Hanafuda IS | I25: Thumb RD | J25: Thumb SC | K25: Magic Bullet OT | L25: Firefist GG
A26: Bleed | G26: Bleed | H26: Tremor
A27: Ring YS | B27: Ring FT | C27: Mancha DQ | D27: Awe RS | E27: Mancha MS | F27: Ring HL | G27: Ring YS | H27: Ring FT | I27: Mancha DQ | J27: Awe RS | K27: Mancha MS | L27: Ring HL
A28: KK HC | B28: KK IS | C28: Mancha RD | D28: Pinky SC | E28: Mancha OT | F28: Priest GG | G28: KK HC | H28: KK IS | I28: Mancha RD | J28: Thumb SC | K28: T OT | L28: Night Awl GG
A29: Tremor | G29: Tremor Souls | H29: Sinking | I29: Burn | J29: Bleed
A30: Heishou YS | B30: Regret FT | C30: T DQ | D30: Awe RS | E30: Thumb MS | F30: D20 HL | G30: Heishou YS | H30: Regret FT | I30: T DQ | J30: FA&S RS | K30: Thumb MS | L30: D20 HL
A31: Oufi HC | B31: Zwei IS | C31: T RD | D31: Thumb SC | E31: T OT | F31: Night Awl GG | G31: Thumb HC | H31: Hanafuda IS | I31: Thumb RD | J31: Thumb SC | K31: Udjat OT | L31: Night Awl GG
A32: Rupture | G32: Heishou | H32: Poise | I32: Rupture
A33: LCE YS | B33: Heishou FT | C33: Lantern DQ | D33: Heishou RS | E33: Cinq MS | F33: Lord HL | G33: Heishou YS | H33: Heishou FT | I33: Heishou DQ | J33: Daiyu RS | K33: Cinq MS | L33: Lord HL
A34: 7 HC | B34: Xichun IS | C34: Devyat RD | D34: Devyat SC | E34: Heishou OT | F34: AEDD GG | G34: Heishou HC | H34: Xichun IS | I34: Heishou RD | J34: Heishou SC | K34: Heishou OT | L34: Heishou GG
A35: Sinking | G35: Sinking Hybrid | H35: Tremor | I35: Poise
A36: TLA YS | B36: WH FT | C36: Heishou DQ | D36: FA&S RS | E36: Dieci MS | F36: R HL | G36: Solemn Lament YS | H36: Index FT | I36: Index DQ | J36: FA&S RS | K36: Dieci MS | L36: Dieci HL
A37: WH HC | B37: Molar IS | C37: KoD RD | D37: Mariachi SC | E37: WH OT | F37: WH GG | G37: WH HC | H37: Hanafuda IS | I37: KoD RD | J37: Mariachi SC | K37: Udjat OT | L37: Lamp GG
A38: Poise | G38: Poise | H38: Sinking
A39: Index YS | B39: Index FT | C39: Index DQ | D39: Daiyu RS | E39: BL MS | F39: FS HL | G39: Index YS | H39: Index FT | I39: Index DQ | J39: FA&S RS | K39: Cinq MS | L39: FS HL
A40: FS HC | B40: WH IS | C40: Heishou RD | D40: Pinky SC | E40: Cinq OT | F40: Heishou GG | G40: FS HC | H40: Hanafuda IS | I40: KoD RD | J40: Pinky/Yan SC | K40: WH OT | L40: WH/Lamp GG
A41: Charge | G41: Charge | H41: Bleed
A42: W YS | B42: MC FT | C42: W DQ | D42: RE&P RS | E42: R MS | F42: R HL | G42: Ring YS | H42: Ring FT | I42: W DQ | J42: RE&P RS | K42: Ring MS | L42: Ring HL
...

Sheet ID Level
A1: ID Name | B1: Sinner | C1: ID Tier | D1: Season | E1: Keyword | F1: Internal ID | G1: Release Date | H1: Acquisition | I1: =IFERROR(__xludf.DUMMYFUNCTION("{""ID Name""; ARRAYFORMULA(LET(fullname, {""["" & A2:A999 & ""] "" & B2:B999}, condition, IF(REGEXMATCH(fullname, ""\[\] ""), """", fullname), IF(H2:H999, condition, """")))}"),"ID Name") -> ID Name | J1: Level | K1: Level Extra | L1: Uptie | M1: Extra Keyword | N1: =IFERROR(__xludf.DUMMYFUNCTION("{""Extractible Unobtained ID""; ARRAYFORMULA( LET( cleanD, SUBSTITUTE(D2:D999, "","", """"), fullname, C2:C999 & "" "" & cleanD & "" "" & ""["" & A2:A999 & ""] "" & B2:B999, condition, IF(NOT(REGEXMATCH(D2:D999 & """", ""Bokgak|Event"")), "&"fullname, """"), IF((H2:H999) + (condition = ""[] "") + (A2:A999 = """"), """", condition) ) )}"),"Extractible Unobtained ID") -> Extractible Unobtained ID | O1: =IFERROR(__xludf.DUMMYFUNCTION("{""Extractible Unobtained ID""; ARRAYFORMULA( LET( cleanD, SUBSTITUTE(D2:D999, "","", """"), fullname, C2:C999 & "" "" & cleanD & "" "" & ""["" & A2:A999 & ""] "" & B2:B999, condition, IF(REGEXMATCH(D2:D999 & """", ""Event|Bokgak""), fulln"&"ame, """"), IF((H2:H999) + (condition = ""[] "") + (A2:A999 = """"), """", condition) ) )}"),"Extractible Unobtained ID") -> Extractible Unobtained ID | P1: Uptie Contender | Q1: Shard Contender
A2: LCB Sinner | B2: Yi Sang | C2: Ø | D2: Standard Fare | E2: Sinking | F2: 1 | G2: =DATE(2023, 2, 27) -> 44984 | H2: TRUE | I2: =IFERROR(__xludf.DUMMYFUNCTION("""COMPUTED_VALUE"""),"[LCB Sinner] Yi Sang") -> [LCB Sinner] Yi Sang | J2: 18 | K2: 935 | L2: 3 | M2: Fragile, Damage Up | N2: =IFERROR(__xludf.DUMMYFUNCTION("""COMPUTED_VALUE"""),"") | O2: =IFERROR(__xludf.DUMMYFUNCTION("""COMPUTED_VALUE"""),"") | P2: Maybe?
A3: LCB Sinner | B3: Faust | C3: Ø | D3: Standard Fare | E3: No Keyword | F3: 2 | G3: =DATE(2023, 2, 27) -> 44984 | H3: TRUE | I3: =IFERROR(__xludf.DUMMYFUNCTION("""COMPUTED_VALUE"""),"[LCB Sinner] Faust") -> [LCB Sinner] Faust | J3: 20 | K3: 139 | L3: 3 | M3: Paralyze, Offense Level Down, Attack Power Down | N3: =IFERROR(__xludf.DUMMYFUNCTION("""COMPUTED_VALUE"""),"") | O3: =IFERROR(__xludf.DUMMYFUNCTION("""COMPUTED_VALUE"""),"") | P3: Maybe?
A4: LCB Sinner | B4: Don Quixote | C4: Ø | D4: Standard Fare | E4: Bleed | F4: 3 | G4: =DATE(2023, 2, 27) -> 44984 | H4: TRUE | I4: =IFERROR(__xludf.DUMMYFUNCTION("""COMPUTED_VALUE"""),"[LCB Sinner] Don Quixote") -> [LCB Sinner] Don Quixote | J4: 18 | K4: 896 | L4: 3 | M4: Haste, Attack Power Up | N4: =IFERROR(__xludf.DUMMYFUNCTION("""COMPUTED_VALUE"""),"") | O4: =IFERROR(__xludf.DUMMYFUNCTION("""COMPUTED_VALUE"""),"") | P4: Maybe?
A5: LCB Sinner | B5: Ryoshu | C5: Ø | D5: Standard Fare | E5: Poise | F5: 4 | G5: =DATE(2023, 2, 27) -> 44984 | H5: TRUE | I5: =IFERROR(__xludf.DUMMYFUNCTION("""COMPUTED_VALUE"""),"[LCB Sinner] Ryoshu") -> [LCB Sinner] Ryoshu | J5: 18 | K5: 937 | L5: 3 | M5: Attack Type DMG/Power Up | N5: =IFERROR(__xludf.DUMMYFUNCTION("""COMPUTED_VALUE"""),"") | O5: =IFERROR(__xludf.DUMMYFUNCTION("""COMPUTED_VALUE"""),"") | P5: Maybe?
A6: LCB Sinner | B6: Meursault | C6: Ø | D6: Standard Fare | E6: Tremor | F6: 5 | G6: =DATE(2023, 2, 27) -> 44984 | H6: TRUE | I6: =IFERROR(__xludf.DUMMYFUNCTION("""COMPUTED_VALUE"""),"[LCB Sinner] Meursault") -> [LCB Sinner] Meursault | J6: 3 | K6: 12 | L6: 3 | M6: Defense Power Up, Protection, Tremor Burst | N6: =IFERROR(__xludf.DUMMYFUNCTION("""COMPUTED_VALUE"""),"") | O6: =IFERROR(__xludf.DUMMYFUNCTION("""COMPUTED_VALUE"""),"") | P6: Maybe?
A7: LCB Sinner | B7: Hong Lu | C7: Ø | D7: Standard Fare | E7: Sinking, Rupture | F7: 6 | G7: =DATE(2023, 2, 27) -> 44984 | H7: TRUE | I7: =IFERROR(__xludf.DUMMYFUNCTION("""COMPUTED_VALUE"""),"[LCB Sinner] Hong Lu") -> [LCB Sinner] Hong Lu | J7: 18 | K7: 898 | L7: 3 | M7: Attack Power Down | N7: =IFERROR(__xludf.DUMMYFUNCTION("""COMPUTED_VALUE"""),"") | O7: =IFERROR(__xludf.DUMMYFUNCTION("""COMPUTED_VALUE"""),"") | P7: Maybe?
A8: LCB Sinner | B8: Heathcliff | C8: Ø | D8: Standard Fare | E8: Tremor | F8: 7 | G8: =DATE(2023, 2, 27) -> 44984 | H8: TRUE | I8: =IFERROR(__xludf.DUMMYFUNCTION("""COMPUTED_VALUE"""),"[LCB Sinner] Heathcliff") -> [LCB Sinner] Heathcliff | J8: 20 | K8: 347 | L8: 3 | M8: Attack Power Up, Damage Up, Tremor Burst | N8: =IFERROR(__xludf.DUMMYFUNCTION("""COMPUTED_VALUE"""),"") | O8: =IFERROR(__xludf.DUMMYFUNCTION("""COMPUTED_VALUE"""),"") | P8: Maybe?
A9: LCB Sinner | B9: Ishmael | C9: Ø | D9: Standard Fare | E9: Tremor | F9: 8 | G9: =DATE(2023, 2, 27) -> 44984 | H9: TRUE | I9: =IFERROR(__xludf.DUMMYFUNCTION("""COMPUTED_VALUE"""),"[LCB Sinner] Ishmael") -> [LCB Sinner] Ishmael | J9: 1 | K9: 0 | L9: 3 | M9: Defense Power Down, Attack Type Fragility, Tremor Burst | N9: =IFERROR(__xludf.DUMMYFUNCTION("""COMPUTED_VALUE"""),"") | O9: =IFERROR(__xludf.DUMMYFUNCTION("""COMPUTED_VALUE"""),"") | P9: Maybe?
A10: LCB Sinner | B10: Rodion | C10: Ø | D10: Standard Fare | E10: Bleed | F10: 9 | G10: =DATE(2023, 2, 27) -> 44984 | H10: TRUE | I10: =IFERROR(__xludf.DUMMYFUNCTION("""COMPUTED_VALUE"""),"[LCB Sinner] Rodion") -> [LCB Sinner] Rodion | J10: 4 | K10: 11 | L10: 3 | N10: =IFERROR(__xludf.DUMMYFUNCTION("""COMPUTED_VALUE"""),"") | O10: =IFERROR(__xludf.DUMMYFUNCTION("""COMPUTED_VALUE"""),"") | P10: Maybe?
A11: LCB Sinner | B11: Sinclair | C11: Ø | D11: Standard Fare | E11: Rupture | F11: 10 | G11: =DATE(2023, 2, 27) -> 44984 | H11: TRUE | I11: =IFERROR(__xludf.DUMMYFUNCTION("""COMPUTED_VALUE"""),"[LCB Sinner] Sinclair") -> [LCB Sinner] Sinclair | J11: 19 | K11: 55 | L11: 3 | M11: Attack Power Up | N11: =IFERROR(__xludf.DUMMYFUNCTION("""COMPUTED_VALUE"""),"") | O11: =IFERROR(__xludf.DUMMYFUNCTION("""COMPUTED_VALUE"""),"") | P11: Maybe?
A12: LCB Sinner | B12: Outis | C12: Ø | D12: Standard Fare | E12: Rupture | F12: 11 | G12: =DATE(2023, 2, 27) -> 44984 | H12: TRUE | I12: =IFERROR(__xludf.DUMMYFUNCTION("""COMPUTED_VALUE"""),"[LCB Sinner] Outis") -> [LCB Sinner] Outis | J12: 19 | K12: 48 | L12: 3 | N12: =IFERROR(__xludf.DUMMYFUNCTION("""COMPUTED_VALUE"""),"") | O12: =IFERROR(__xludf.DUMMYFUNCTION("""COMPUTED_VALUE"""),"") | P12: Maybe?
